2024-05-26 17:31:13,685 : INFO : Start of training model...
2024-05-26 17:31:13,685 : INFO : Run_id: 2024-05-26_173113_44889816
2024-05-26 17:31:13,685 : INFO : Start of data load, validation, and transformation for trainset
2024-05-26 17:31:13,685 : INFO : Start of archiving old reject files...
2024-05-26 17:31:13,685 : INFO : End of archiving old reject files...
2024-05-26 17:31:13,685 : INFO : Start of archiving old validation files...
2024-05-26 17:31:13,686 : INFO : End of archiving old validation files...
2024-05-26 17:31:13,689 : INFO : Start of archiving old processed files...
2024-05-26 17:31:13,689 : INFO : End of archiving old processed files...
2024-05-26 17:31:13,689 : INFO : Start of archiving old result files...
2024-05-26 17:31:13,689 : INFO : End of archiving old result files...
2024-05-26 17:31:13,689 : INFO : Start of reading values from schema...
2024-05-26 17:31:13,689 : INFO : End of reading values from schema...
2024-05-26 17:31:13,689 : INFO : Start of validating column length...
2024-05-26 17:31:13,689 : INFO : End of validating column length...
2024-05-26 17:31:13,689 : INFO : Start of validating missing values...
2024-05-26 17:31:13,689 : INFO : End of validating missing values...
2024-05-26 17:31:13,689 : INFO : Start of replacing missing values with NULL...
2024-05-26 17:31:13,690 : INFO : End of replacing missing values with NULL...
2024-05-26 17:31:13,690 : INFO : Start of creating table...
2024-05-26 17:31:13,690 : INFO : Opened training database successfully
2024-05-26 17:31:13,690 : INFO : Tables created successfully
2024-05-26 17:31:13,690 : INFO : Closed training_raw_data_t database successfilly
2024-05-26 17:31:13,690 : INFO : End of creating table...
2024-05-26 17:31:13,691 : INFO : Opened training database successfully
2024-05-26 17:31:13,691 : INFO : Start of inserting data into table...
2024-05-26 17:31:13,691 : INFO : End of inserting data into table...
2024-05-26 17:31:13,691 : INFO : Start of exporting data into CSV...
2024-05-26 17:31:13,691 : INFO : Opened training database successfully
2024-05-26 17:31:13,736 : INFO : End of exporting data to CSV...
2024-05-26 17:31:13,737 : INFO : Start of moving processed files...
2024-05-26 17:31:13,737 : INFO : End of moving processed files...
2024-05-26 17:31:13,737 : INFO : End of data load, validation, and transformation
2024-05-26 17:31:13,737 : INFO : Start of preprocessing training data...
2024-05-26 17:31:13,737 : INFO : Start of reading dataset...
2024-05-26 17:31:13,753 : INFO : End of reading dataset....
2024-05-26 17:31:13,754 : INFO : Start of dropping columns...
2024-05-26 17:31:13,754 : INFO : End of dropping columns...
2024-05-26 17:31:13,754 : INFO : Start of feature encoding...
2024-05-26 17:31:13,756 : INFO : End of feature encoding...
2024-05-26 17:31:13,757 : INFO : Start of dropping columns...
2024-05-26 17:31:13,757 : INFO : End of dropping columns...
2024-05-26 17:31:13,757 : INFO : Start of finding missing values...
2024-05-26 17:31:13,760 : INFO : End of finding missing values...
2024-05-26 17:31:13,761 : INFO : Start of imputing missing values...
2024-05-26 17:31:13,772 : INFO : End of imputing missing values...
2024-05-26 17:31:13,772 : INFO : Start of splitting features and label
2024-05-26 17:31:13,772 : INFO : End of splitting features and label
2024-05-26 17:31:13,772 : INFO : End of preprocessing training data...
2024-05-26 17:31:13,773 : INFO : Start of elbow plotting...
2024-05-26 17:31:14,171 : INFO : Optimum number of clusters: 3
2024-05-26 17:31:14,171 : INFO : End of elbow plotting...
2024-05-26 17:31:14,171 : INFO : Start of creating clusters...
2024-05-26 17:31:14,180 : INFO : Start of Save Models
2024-05-26 17:31:14,180 : INFO : Start of Save Models
2024-05-26 17:31:14,181 : ERROR : Exception raised while saving model: [Errno 2] No such file or directory: 'apps/models\\Kmeans/Kmeans.sav'
Traceback (most recent call last):
  File "C:\Users\RETRETA\Documents\Python\ML Upskill\employee-churn-ML-e2e\apps\core\file_operation.py", line 25, in save_model
    with open(path + '/' + file_name + '.sav', 'wb') as f:
FileNotFoundError: [Errno 2] No such file or directory: 'apps/models\\Kmeans/Kmeans.sav'
2024-05-26 17:31:14,181 : ERROR : Exception raised while saving model: [Errno 2] No such file or directory: 'apps/models\\Kmeans/Kmeans.sav'
Traceback (most recent call last):
  File "C:\Users\RETRETA\Documents\Python\ML Upskill\employee-churn-ML-e2e\apps\core\file_operation.py", line 25, in save_model
    with open(path + '/' + file_name + '.sav', 'wb') as f:
FileNotFoundError: [Errno 2] No such file or directory: 'apps/models\\Kmeans/Kmeans.sav'
2024-05-26 17:31:14,181 : ERROR : Exception raised while creating clusters: 
Traceback (most recent call last):
  File "C:\Users\RETRETA\Documents\Python\ML Upskill\employee-churn-ML-e2e\apps\core\file_operation.py", line 25, in save_model
    with open(path + '/' + file_name + '.sav', 'wb') as f:
FileNotFoundError: [Errno 2] No such file or directory: 'apps/models\\Kmeans/Kmeans.sav'

During handling of the above exception, another exception occurred:

Traceback (most recent call last):
  File "C:\Users\RETRETA\Documents\Python\ML Upskill\employee-churn-ML-e2e\apps\tuning\cluster.py", line 56, in create_clusters
    self.saveModel = self.fileOperation.save_model(self.kmeans, 'Kmeans')
  File "C:\Users\RETRETA\Documents\Python\ML Upskill\employee-churn-ML-e2e\apps\core\file_operation.py", line 33, in save_model
    raise Exception()
Exception
2024-05-26 17:31:14,181 : ERROR : Training model unsuccessful: 
Traceback (most recent call last):
  File "C:\Users\RETRETA\Documents\Python\ML Upskill\employee-churn-ML-e2e\apps\core\file_operation.py", line 25, in save_model
    with open(path + '/' + file_name + '.sav', 'wb') as f:
FileNotFoundError: [Errno 2] No such file or directory: 'apps/models\\Kmeans/Kmeans.sav'

During handling of the above exception, another exception occurred:

Traceback (most recent call last):
  File "C:\Users\RETRETA\Documents\Python\ML Upskill\employee-churn-ML-e2e\apps\training\train_model.py", line 45, in train_model
    self.X = self.cluster.create_clusters(self.X, number_of_clusters)
  File "C:\Users\RETRETA\Documents\Python\ML Upskill\employee-churn-ML-e2e\apps\tuning\cluster.py", line 67, in create_clusters
    raise e
  File "C:\Users\RETRETA\Documents\Python\ML Upskill\employee-churn-ML-e2e\apps\tuning\cluster.py", line 56, in create_clusters
    self.saveModel = self.fileOperation.save_model(self.kmeans, 'Kmeans')
  File "C:\Users\RETRETA\Documents\Python\ML Upskill\employee-churn-ML-e2e\apps\core\file_operation.py", line 33, in save_model
    raise Exception()
Exception
