2024-05-26 17:45:47,037 : INFO : Start of training model...
2024-05-26 17:45:47,037 : INFO : Run_id: 2024-05-26_174547_49102005
2024-05-26 17:45:47,037 : INFO : Start of data load, validation, and transformation for trainset
2024-05-26 17:45:47,037 : INFO : Start of archiving old reject files...
2024-05-26 17:45:47,037 : INFO : End of archiving old reject files...
2024-05-26 17:45:47,038 : INFO : Start of archiving old validation files...
2024-05-26 17:45:47,039 : INFO : End of archiving old validation files...
2024-05-26 17:45:47,039 : INFO : Start of archiving old processed files...
2024-05-26 17:45:47,039 : INFO : End of archiving old processed files...
2024-05-26 17:45:47,039 : INFO : Start of archiving old result files...
2024-05-26 17:45:47,039 : INFO : End of archiving old result files...
2024-05-26 17:45:47,039 : INFO : Start of reading values from schema...
2024-05-26 17:45:47,039 : INFO : End of reading values from schema...
2024-05-26 17:45:47,039 : INFO : Start of validating column length...
2024-05-26 17:45:47,040 : INFO : End of validating column length...
2024-05-26 17:45:47,040 : INFO : Start of validating missing values...
2024-05-26 17:45:47,040 : INFO : End of validating missing values...
2024-05-26 17:45:47,040 : INFO : Start of replacing missing values with NULL...
2024-05-26 17:45:47,040 : INFO : End of replacing missing values with NULL...
2024-05-26 17:45:47,040 : INFO : Start of creating table...
2024-05-26 17:45:47,040 : INFO : Opened training database successfully
2024-05-26 17:45:47,041 : INFO : Tables created successfully
2024-05-26 17:45:47,041 : INFO : Closed training_raw_data_t database successfilly
2024-05-26 17:45:47,041 : INFO : End of creating table...
2024-05-26 17:45:47,041 : INFO : Opened training database successfully
2024-05-26 17:45:47,041 : INFO : Start of inserting data into table...
2024-05-26 17:45:47,041 : INFO : End of inserting data into table...
2024-05-26 17:45:47,041 : INFO : Start of exporting data into CSV...
2024-05-26 17:45:47,041 : INFO : Opened training database successfully
2024-05-26 17:45:47,090 : INFO : End of exporting data to CSV...
2024-05-26 17:45:47,091 : INFO : Start of moving processed files...
2024-05-26 17:45:47,092 : INFO : End of moving processed files...
2024-05-26 17:45:47,092 : INFO : End of data load, validation, and transformation
2024-05-26 17:45:47,092 : INFO : Start of preprocessing training data...
2024-05-26 17:45:47,092 : INFO : Start of reading dataset...
2024-05-26 17:45:47,107 : INFO : End of reading dataset....
2024-05-26 17:45:47,108 : INFO : Start of dropping columns...
2024-05-26 17:45:47,109 : INFO : End of dropping columns...
2024-05-26 17:45:47,109 : INFO : Start of feature encoding...
2024-05-26 17:45:47,111 : INFO : End of feature encoding...
2024-05-26 17:45:47,112 : INFO : Start of dropping columns...
2024-05-26 17:45:47,112 : INFO : End of dropping columns...
2024-05-26 17:45:47,112 : INFO : Start of finding missing values...
2024-05-26 17:45:47,116 : INFO : End of finding missing values...
2024-05-26 17:45:47,116 : INFO : Start of imputing missing values...
2024-05-26 17:45:47,127 : INFO : End of imputing missing values...
2024-05-26 17:45:47,127 : INFO : Start of splitting features and label
2024-05-26 17:45:47,127 : INFO : End of splitting features and label
2024-05-26 17:45:47,127 : INFO : End of preprocessing training data...
2024-05-26 17:45:47,128 : INFO : Start of elbow plotting...
2024-05-26 17:45:47,533 : INFO : Optimum number of clusters: 3
2024-05-26 17:45:47,533 : INFO : End of elbow plotting...
2024-05-26 17:45:47,534 : INFO : Start of creating clusters...
2024-05-26 17:45:47,541 : INFO : Start of Save Models
2024-05-26 17:45:47,541 : INFO : Start of Save Models
2024-05-26 17:45:47,543 : ERROR : Exception raised while saving model: [Errno 2] No such file or directory: 'apps/models\\KMeans/KMeans.sav'
Traceback (most recent call last):
  File "C:\Users\RETRETA\Documents\Python\ML Upskill\employee-churn-ML-e2e\apps\core\file_operation.py", line 25, in save_model
    with open(path + '/' + file_name + '.sav', 'wb') as f:
FileNotFoundError: [Errno 2] No such file or directory: 'apps/models\\KMeans/KMeans.sav'
2024-05-26 17:45:47,543 : ERROR : Exception raised while saving model: [Errno 2] No such file or directory: 'apps/models\\KMeans/KMeans.sav'
Traceback (most recent call last):
  File "C:\Users\RETRETA\Documents\Python\ML Upskill\employee-churn-ML-e2e\apps\core\file_operation.py", line 25, in save_model
    with open(path + '/' + file_name + '.sav', 'wb') as f:
FileNotFoundError: [Errno 2] No such file or directory: 'apps/models\\KMeans/KMeans.sav'
2024-05-26 17:45:47,544 : ERROR : Exception raised while creating clusters: 
Traceback (most recent call last):
  File "C:\Users\RETRETA\Documents\Python\ML Upskill\employee-churn-ML-e2e\apps\core\file_operation.py", line 25, in save_model
    with open(path + '/' + file_name + '.sav', 'wb') as f:
FileNotFoundError: [Errno 2] No such file or directory: 'apps/models\\KMeans/KMeans.sav'

During handling of the above exception, another exception occurred:

Traceback (most recent call last):
  File "C:\Users\RETRETA\Documents\Python\ML Upskill\employee-churn-ML-e2e\apps\tuning\cluster.py", line 63, in create_clusters
    self.saveModel = self.fileOperation.save_model(
  File "C:\Users\RETRETA\Documents\Python\ML Upskill\employee-churn-ML-e2e\apps\core\file_operation.py", line 33, in save_model
    raise Exception()
Exception
2024-05-26 17:45:47,544 : ERROR : Training model unsuccessful: 
Traceback (most recent call last):
  File "C:\Users\RETRETA\Documents\Python\ML Upskill\employee-churn-ML-e2e\apps\core\file_operation.py", line 25, in save_model
    with open(path + '/' + file_name + '.sav', 'wb') as f:
FileNotFoundError: [Errno 2] No such file or directory: 'apps/models\\KMeans/KMeans.sav'

During handling of the above exception, another exception occurred:

Traceback (most recent call last):
  File "C:\Users\RETRETA\Documents\Python\ML Upskill\employee-churn-ML-e2e\apps\training\train_model.py", line 45, in train_model
    self.X = self.cluster.create_clusters(self.X, number_of_clusters)
  File "C:\Users\RETRETA\Documents\Python\ML Upskill\employee-churn-ML-e2e\apps\tuning\cluster.py", line 77, in create_clusters
    raise e
  File "C:\Users\RETRETA\Documents\Python\ML Upskill\employee-churn-ML-e2e\apps\tuning\cluster.py", line 63, in create_clusters
    self.saveModel = self.fileOperation.save_model(
  File "C:\Users\RETRETA\Documents\Python\ML Upskill\employee-churn-ML-e2e\apps\core\file_operation.py", line 33, in save_model
    raise Exception()
Exception
