2024-05-26 16:54:56,105 : INFO : Start of training model...
2024-05-26 16:54:56,105 : INFO : Run_id: 2024-05-26_165456_25944399
2024-05-26 16:54:56,105 : INFO : Start of data load, validation, and transformation for trainset
2024-05-26 16:54:56,105 : INFO : Start of archiving old reject files...
2024-05-26 16:54:56,105 : INFO : End of archiving old reject files...
2024-05-26 16:54:56,105 : INFO : Start of archiving old validation files...
2024-05-26 16:54:56,105 : INFO : End of archiving old validation files...
2024-05-26 16:54:56,105 : INFO : Start of archiving old processed files...
2024-05-26 16:54:56,105 : INFO : End of archiving old processed files...
2024-05-26 16:54:56,105 : INFO : Start of archiving old result files...
2024-05-26 16:54:56,107 : INFO : End of archiving old result files...
2024-05-26 16:54:56,107 : INFO : Start of reading values from schema...
2024-05-26 16:54:56,107 : ERROR : Exception raised when reading values from schema: name 'r' is not defined
Traceback (most recent call last):
  File "C:\Users\RETRETA\Documents\Python\ML Upskill\employee-churn-ML-e2e\apps\ingestion\load_validate.py", line 22, in read_values_from_schema
    with open(f'apps/database/{schema_file}.json', r) as f:
NameError: name 'r' is not defined
2024-05-26 16:54:56,107 : ERROR : Encountered eror during data load, validation, and transformation for trainset
Traceback (most recent call last):
  File "C:\Users\RETRETA\Documents\Python\ML Upskill\employee-churn-ML-e2e\apps\ingestion\load_validate.py", line 175, in validate_trainset
    column_names, number_of_columns = self.read_values_from_schema('schema_train')
  File "C:\Users\RETRETA\Documents\Python\ML Upskill\employee-churn-ML-e2e\apps\ingestion\load_validate.py", line 40, in read_values_from_schema
    raise e
  File "C:\Users\RETRETA\Documents\Python\ML Upskill\employee-churn-ML-e2e\apps\ingestion\load_validate.py", line 22, in read_values_from_schema
    with open(f'apps/database/{schema_file}.json', r) as f:
NameError: name 'r' is not defined
2024-05-26 16:54:56,107 : INFO : Start of preprocessing training data...
2024-05-26 16:54:56,107 : INFO : Start of reading dataset...
2024-05-26 16:54:56,108 : ERROR : Exception rasied while reading dataset: [Errno 2] No such file or directory: 'data/training_data_validation/InputFile.csv'
Traceback (most recent call last):
  File "C:\Users\RETRETA\Documents\Python\ML Upskill\employee-churn-ML-e2e\apps\preprocess\preprocessor.py", line 19, in get_data
    self.data = pd.read_csv(f'{self.data_path}_validation/InputFile.csv')
  File "C:\Users\RETRETA\anaconda3\envs\employee-churn-e2e-env\lib\site-packages\pandas\io\parsers\readers.py", line 1026, in read_csv
    return _read(filepath_or_buffer, kwds)
  File "C:\Users\RETRETA\anaconda3\envs\employee-churn-e2e-env\lib\site-packages\pandas\io\parsers\readers.py", line 620, in _read
    parser = TextFileReader(filepath_or_buffer, **kwds)
  File "C:\Users\RETRETA\anaconda3\envs\employee-churn-e2e-env\lib\site-packages\pandas\io\parsers\readers.py", line 1620, in __init__
    self._engine = self._make_engine(f, self.engine)
  File "C:\Users\RETRETA\anaconda3\envs\employee-churn-e2e-env\lib\site-packages\pandas\io\parsers\readers.py", line 1880, in _make_engine
    self.handles = get_handle(
  File "C:\Users\RETRETA\anaconda3\envs\employee-churn-e2e-env\lib\site-packages\pandas\io\common.py", line 873, in get_handle
    handle = open(
FileNotFoundError: [Errno 2] No such file or directory: 'data/training_data_validation/InputFile.csv'
2024-05-26 16:54:56,110 : ERROR : Exception raised while preprocessing training data: [Errno 2] No such file or directory: 'data/training_data_validation/InputFile.csv'
Traceback (most recent call last):
  File "C:\Users\RETRETA\Documents\Python\ML Upskill\employee-churn-ML-e2e\apps\preprocess\preprocessor.py", line 146, in preprocess_trainset
    data = self.get_data()
  File "C:\Users\RETRETA\Documents\Python\ML Upskill\employee-churn-ML-e2e\apps\preprocess\preprocessor.py", line 23, in get_data
    raise e
  File "C:\Users\RETRETA\Documents\Python\ML Upskill\employee-churn-ML-e2e\apps\preprocess\preprocessor.py", line 19, in get_data
    self.data = pd.read_csv(f'{self.data_path}_validation/InputFile.csv')
  File "C:\Users\RETRETA\anaconda3\envs\employee-churn-e2e-env\lib\site-packages\pandas\io\parsers\readers.py", line 1026, in read_csv
    return _read(filepath_or_buffer, kwds)
  File "C:\Users\RETRETA\anaconda3\envs\employee-churn-e2e-env\lib\site-packages\pandas\io\parsers\readers.py", line 620, in _read
    parser = TextFileReader(filepath_or_buffer, **kwds)
  File "C:\Users\RETRETA\anaconda3\envs\employee-churn-e2e-env\lib\site-packages\pandas\io\parsers\readers.py", line 1620, in __init__
    self._engine = self._make_engine(f, self.engine)
  File "C:\Users\RETRETA\anaconda3\envs\employee-churn-e2e-env\lib\site-packages\pandas\io\parsers\readers.py", line 1880, in _make_engine
    self.handles = get_handle(
  File "C:\Users\RETRETA\anaconda3\envs\employee-churn-e2e-env\lib\site-packages\pandas\io\common.py", line 873, in get_handle
    handle = open(
FileNotFoundError: [Errno 2] No such file or directory: 'data/training_data_validation/InputFile.csv'
2024-05-26 16:54:56,110 : ERROR : Training model unsuccessful: [Errno 2] No such file or directory: 'data/training_data_validation/InputFile.csv'
Traceback (most recent call last):
  File "C:\Users\RETRETA\Documents\Python\ML Upskill\employee-churn-ML-e2e\apps\training\train_model.py", line 34, in train_model
    self.X, self.y = self.preProcess.preprocess_trainset()
  File "C:\Users\RETRETA\Documents\Python\ML Upskill\employee-churn-ML-e2e\apps\preprocess\preprocessor.py", line 166, in preprocess_trainset
    raise e
  File "C:\Users\RETRETA\Documents\Python\ML Upskill\employee-churn-ML-e2e\apps\preprocess\preprocessor.py", line 146, in preprocess_trainset
    data = self.get_data()
  File "C:\Users\RETRETA\Documents\Python\ML Upskill\employee-churn-ML-e2e\apps\preprocess\preprocessor.py", line 23, in get_data
    raise e
  File "C:\Users\RETRETA\Documents\Python\ML Upskill\employee-churn-ML-e2e\apps\preprocess\preprocessor.py", line 19, in get_data
    self.data = pd.read_csv(f'{self.data_path}_validation/InputFile.csv')
  File "C:\Users\RETRETA\anaconda3\envs\employee-churn-e2e-env\lib\site-packages\pandas\io\parsers\readers.py", line 1026, in read_csv
    return _read(filepath_or_buffer, kwds)
  File "C:\Users\RETRETA\anaconda3\envs\employee-churn-e2e-env\lib\site-packages\pandas\io\parsers\readers.py", line 620, in _read
    parser = TextFileReader(filepath_or_buffer, **kwds)
  File "C:\Users\RETRETA\anaconda3\envs\employee-churn-e2e-env\lib\site-packages\pandas\io\parsers\readers.py", line 1620, in __init__
    self._engine = self._make_engine(f, self.engine)
  File "C:\Users\RETRETA\anaconda3\envs\employee-churn-e2e-env\lib\site-packages\pandas\io\parsers\readers.py", line 1880, in _make_engine
    self.handles = get_handle(
  File "C:\Users\RETRETA\anaconda3\envs\employee-churn-e2e-env\lib\site-packages\pandas\io\common.py", line 873, in get_handle
    handle = open(
FileNotFoundError: [Errno 2] No such file or directory: 'data/training_data_validation/InputFile.csv'
