2024-05-26 17:12:13,731 : INFO : Start of training model...
2024-05-26 17:12:13,731 : INFO : Run_id: 2024-05-26_171213_86073924
2024-05-26 17:12:13,731 : INFO : Start of data load, validation, and transformation for trainset
2024-05-26 17:12:13,731 : INFO : Start of archiving old reject files...
2024-05-26 17:12:13,731 : INFO : End of archiving old reject files...
2024-05-26 17:12:13,731 : INFO : Start of archiving old validation files...
2024-05-26 17:12:13,732 : ERROR : Exception raised while archiving old files: [Errno 2] No such file or directory: 'data/training_data_validationInputFile.csv'
Traceback (most recent call last):
  File "C:\Users\RETRETA\anaconda3\envs\employee-churn-e2e-env\lib\shutil.py", line 825, in move
    os.rename(src, real_dst)
FileNotFoundError: [WinError 2] The system cannot find the file specified: 'data/training_data_validationInputFile.csv' -> 'data/training_data_archive/validation_2024-05-26_171213\\training_data_validationInputFile.csv'

During handling of the above exception, another exception occurred:

Traceback (most recent call last):
  File "C:\Users\RETRETA\Documents\Python\ML Upskill\employee-churn-ML-e2e\apps\ingestion\load_validate.py", line 142, in archive_old_files
    process_archival('validation')
  File "C:\Users\RETRETA\Documents\Python\ML Upskill\employee-churn-ML-e2e\apps\ingestion\load_validate.py", line 134, in process_archival
    shutil.move(source + f, dest)
  File "C:\Users\RETRETA\anaconda3\envs\employee-churn-e2e-env\lib\shutil.py", line 845, in move
    copy_function(src, real_dst)
  File "C:\Users\RETRETA\anaconda3\envs\employee-churn-e2e-env\lib\shutil.py", line 444, in copy2
    copyfile(src, dst, follow_symlinks=follow_symlinks)
  File "C:\Users\RETRETA\anaconda3\envs\employee-churn-e2e-env\lib\shutil.py", line 264, in copyfile
    with open(src, 'rb') as fsrc:
FileNotFoundError: [Errno 2] No such file or directory: 'data/training_data_validationInputFile.csv'
2024-05-26 17:12:13,738 : ERROR : Encountered eror during data load, validation, and transformation for trainset
Traceback (most recent call last):
  File "C:\Users\RETRETA\anaconda3\envs\employee-churn-e2e-env\lib\shutil.py", line 825, in move
    os.rename(src, real_dst)
FileNotFoundError: [WinError 2] The system cannot find the file specified: 'data/training_data_validationInputFile.csv' -> 'data/training_data_archive/validation_2024-05-26_171213\\training_data_validationInputFile.csv'

During handling of the above exception, another exception occurred:

Traceback (most recent call last):
  File "C:\Users\RETRETA\Documents\Python\ML Upskill\employee-churn-ML-e2e\apps\ingestion\load_validate.py", line 173, in validate_trainset
    self.archive_old_files()
  File "C:\Users\RETRETA\Documents\Python\ML Upskill\employee-churn-ML-e2e\apps\ingestion\load_validate.py", line 152, in archive_old_files
    raise e
  File "C:\Users\RETRETA\Documents\Python\ML Upskill\employee-churn-ML-e2e\apps\ingestion\load_validate.py", line 142, in archive_old_files
    process_archival('validation')
  File "C:\Users\RETRETA\Documents\Python\ML Upskill\employee-churn-ML-e2e\apps\ingestion\load_validate.py", line 134, in process_archival
    shutil.move(source + f, dest)
  File "C:\Users\RETRETA\anaconda3\envs\employee-churn-e2e-env\lib\shutil.py", line 845, in move
    copy_function(src, real_dst)
  File "C:\Users\RETRETA\anaconda3\envs\employee-churn-e2e-env\lib\shutil.py", line 444, in copy2
    copyfile(src, dst, follow_symlinks=follow_symlinks)
  File "C:\Users\RETRETA\anaconda3\envs\employee-churn-e2e-env\lib\shutil.py", line 264, in copyfile
    with open(src, 'rb') as fsrc:
FileNotFoundError: [Errno 2] No such file or directory: 'data/training_data_validationInputFile.csv'
2024-05-26 17:12:13,739 : INFO : Start of preprocessing training data...
2024-05-26 17:12:13,739 : INFO : Start of reading dataset...
2024-05-26 17:12:13,749 : INFO : End of reading dataset....
2024-05-26 17:12:13,750 : INFO : Start of dropping columns...
2024-05-26 17:12:13,754 : INFO : End of dropping columns...
2024-05-26 17:12:13,754 : INFO : Start of feature encoding...
2024-05-26 17:12:13,759 : INFO : End of feature encoding...
2024-05-26 17:12:13,759 : INFO : Start of dropping columns...
2024-05-26 17:12:13,760 : INFO : End of dropping columns...
2024-05-26 17:12:13,760 : INFO : Start of finding missing values...
2024-05-26 17:12:13,765 : INFO : End of finding missing values...
2024-05-26 17:12:13,765 : INFO : Start of imputing missing values...
2024-05-26 17:12:13,780 : INFO : End of imputing missing values...
2024-05-26 17:12:13,780 : INFO : Start of splitting features and label
2024-05-26 17:12:13,780 : ERROR : Exception raised while splitting features and label: 'NoneType' object has no attribute 'drop'
Traceback (most recent call last):
  File "C:\Users\RETRETA\Documents\Python\ML Upskill\employee-churn-ML-e2e\apps\preprocess\preprocessor.py", line 108, in split_features_label
    self.X = self.data.drop(labels=label_name, axis=1)
AttributeError: 'NoneType' object has no attribute 'drop'
2024-05-26 17:12:13,781 : ERROR : Exception raised while preprocessing training data: 'NoneType' object has no attribute 'drop'
Traceback (most recent call last):
  File "C:\Users\RETRETA\Documents\Python\ML Upskill\employee-churn-ML-e2e\apps\preprocess\preprocessor.py", line 162, in preprocess_trainset
    self.X, self.y = self.split_features_label(data, label_name='left')
  File "C:\Users\RETRETA\Documents\Python\ML Upskill\employee-churn-ML-e2e\apps\preprocess\preprocessor.py", line 116, in split_features_label
    raise e
  File "C:\Users\RETRETA\Documents\Python\ML Upskill\employee-churn-ML-e2e\apps\preprocess\preprocessor.py", line 108, in split_features_label
    self.X = self.data.drop(labels=label_name, axis=1)
AttributeError: 'NoneType' object has no attribute 'drop'
2024-05-26 17:12:13,781 : ERROR : Training model unsuccessful: 'NoneType' object has no attribute 'drop'
Traceback (most recent call last):
  File "C:\Users\RETRETA\Documents\Python\ML Upskill\employee-churn-ML-e2e\apps\training\train_model.py", line 34, in train_model
    self.X, self.y = self.preProcess.preprocess_trainset()
  File "C:\Users\RETRETA\Documents\Python\ML Upskill\employee-churn-ML-e2e\apps\preprocess\preprocessor.py", line 168, in preprocess_trainset
    raise e
  File "C:\Users\RETRETA\Documents\Python\ML Upskill\employee-churn-ML-e2e\apps\preprocess\preprocessor.py", line 162, in preprocess_trainset
    self.X, self.y = self.split_features_label(data, label_name='left')
  File "C:\Users\RETRETA\Documents\Python\ML Upskill\employee-churn-ML-e2e\apps\preprocess\preprocessor.py", line 116, in split_features_label
    raise e
  File "C:\Users\RETRETA\Documents\Python\ML Upskill\employee-churn-ML-e2e\apps\preprocess\preprocessor.py", line 108, in split_features_label
    self.X = self.data.drop(labels=label_name, axis=1)
AttributeError: 'NoneType' object has no attribute 'drop'
